Workbook

Sheet Acessos CD - 010225 - 280226
A1: Acessos | B1: Nome do serviço | C1: Órgão | D1: <<< fev25 a fev26 | E1: Representatividade | F1: Qtd acesso/dia por 1 ano | G1: =SUM(A2:A757) -> 17636843
A2: 5262715 | B2: CADRio Agendamento | C2: Secretaria Municipal de Assistência Social - SMAS | E2: =A2/G$1 -> 0.29839326 | F2: =A2/365 -> 14418.397
A3: 2470819 | B3: IPTU 2025 | C3: Secretaria Municipal de Fazenda e Planejamento - SMFP | E3: =A3/G$1 -> 0.14009418 | F3: =A3/365 -> 6769.3671 | G3: 318
A4: 1635914 | B4: Alvará - Consulta Prévia de Local | C4: 1403 - Secretaria Municipal de Fazenda / Coordenadoria de Licenciamento e Fiscalização | E4: =A4/G$1 -> 0.092755489 | F4: =A4/365 -> 4481.9562 | G4: =G3/757 -> 0.42007926
A5: 742843 | B5: IPTU - Certidão de Situação Fiscal e Enfitêutica | C5: Secretaria Municipal de Fazenda e Planejamento - SMFP | E5: =A5/G$1 -> 0.042118819 | F5: =A5/365 -> 2035.1863
A6: 425988 | B6: Informações sobre o Cadastro Único | C6: Secretaria Municipal de Assistência Social - SMAS | E6: =A6/G$1 -> 0.024153302 | F6: =A6/365 -> 1167.0904
A7: 376350 | B7: Licença Sanitária de Funcionamento | C7: Secretaria Municipal de Saúde / Instituto Municipal de Vigilância Sanitária, Vigilância de Zoonoses e de Inspeção Agropecuária - IVISA-RIO | E7: =A7/G$1 -> 0.021338853 | F7: =A7/365 -> 1031.0959
A8: 360551 | B8: IPTU 2024 e anteriores - cobrança na Fazenda | C8: Secretaria Municipal de Fazenda e Planejamento - SMFP | E8: =A8/G$1 -> 0.020443058 | F8: =A8/365 -> 987.81096
A9: 313304 | B9: Dívida Ativa - Consultar débitos de IPTU | C9: Procuradoria Geral do Município do Rio de Janeiro - PGM | E9: =A9/G$1 -> 0.017764177 | F9: =A9/365 -> 858.36712
A10: 270260 | B10: ITBI – Simulação de Valor e Pedido de Guia | C10: Secretaria Municipal de Fazenda e Planejamento - SMFP | E10: =A10/G$1 -> 0.015323604 | F10: =A10/365 -> 740.43836
A11: 248917 | B11: Multa de Trânsito - Consulta de Multa | C11: Secretaria Municipal de Transportes - SMTR | E11: =A11/G$1 -> 0.014113467 | F11: =A11/365 -> 681.96438
A12: 208538 | B12: IPTU - Certidão de Elementos Cadastrais | C12: Secretaria Municipal de Fazenda e Planejamento - SMFP | E12: =A12/G$1 -> 0.011823998 | F12: =A12/365 -> 571.33699
A13: 203554 | B13: Censo Cadastral Previdenciário - Previ-Rio | C13: Instituto de Previdência e Assistência do Município do Rio de Janeiro - PREVI-RIO | E13: =A13/G$1 -> 0.011541408 | F13: =A13/365 -> 557.68219
A14: 195446 | B14: ISS – Comprovante de Inscrição e de Situação Cadastral | C14: Secretaria Municipal de Fazenda e Planejamento - SMFP | E14: =A14/G$1 -> 0.011081688 | F14: =A14/365 -> 535.46849
A15: 184469 | B15: ISS - Certidão de Situação Fiscal | C15: Secretaria Municipal de Fazenda e Planejamento - SMFP | E15: =A15/G$1 -> 0.010459298 | F15: =A15/365 -> 505.39452
A16: 163586 | B16: SMPDA - Programa Bicho Rio - Esterilização gratuita de cães e gatos | C16: Secretaria Municipal de Proteção e Defesa dos Animais - SMPDA | E16: =A16/G$1 -> 0.0092752427 | F16: =A16/365 -> 448.18082
... A757: 21 | B757: Parcelamento em casos de posse em Dívida Ativa | C757: Procuradoria Geral do Município do Rio de Janeiro - PGM | E757: =A757/G$1 -> 1.1906893e-06 | F757: =A757/365 -> 0.057534247

Sheet Tabela dinâmica_CD
D1: Manter? | E1: Avaliação 1746
D2: S
D3: N

Sheet # chamados inicial
B1: ID_Subtipo | C1: UO | D1: Subtipos de Serviços | E1: Volume | G1: TEM SERVIÇO? | H1: ID_Subtipo | I1: UO | J1: Subtipos de Informações | K1: Volume
B2: 2966 | C2: =VLOOKUP(B2,'subtipo ativo'!A:M,2,0) -> GM-RIO - Guarda Municipal do Rio de Janeiro | D2: Fiscalização de estacionamento irregular de veículo | E2: 201219 | G2: =VLOOKUP(H2,B:E,1,0) -> 2966 | H2: 2966 | I2: =VLOOKUP(H2,'subtipo ativo'!A:M,2,0) -> GM-RIO - Guarda Municipal do Rio de Janeiro | J2: Fiscalização de estacionamento irregular de veículo | K2: 201219
B3: 1325 | C3: =VLOOKUP(B3,'subtipo ativo'!A:M,2,0) -> COMLURB - Companhia Municipal de Limpeza Urbana | D3: Remoção de entulho | E3: 135183 | G3: =VLOOKUP(H3,B:E,1,0) -> 1325 | H3: 1325 | I3: =VLOOKUP(H3,'subtipo ativo'!A:M,2,0) -> COMLURB - Companhia Municipal de Limpeza Urbana | J3: Remoção de entulho | K3: 135183
B4: 5799 | C4: =VLOOKUP(B4,'subtipo ativo'!A:M,2,0) -> Ouvidoria RIOLUZ | D4: Reparo de luminária | E4: 91196 | G4: =VLOOKUP(H4,B:E,1,0) -> 5799 | H4: 5799 | I4: =VLOOKUP(H4,'subtipo ativo'!A:M,2,0) -> Ouvidoria RIOLUZ | J4: Reparo de luminária | K4: 91196
B5: 78 | C5: =VLOOKUP(B5,'subtipo ativo'!A:M,2,0) -> CGC - Coordenadoria Geral de Conservação | D5: Reparo de buraco, deformação ou afundamento na pista | E5: 51060 | G5: =VLOOKUP(H5,B:E,1,0) -> 1298 | H5: 1298 | I5: =VLOOKUP(H5,'subtipo ativo'!A:M,2,0) -> COMLURB - Companhia Municipal de Limpeza Urbana | J5: Remoção de resíduos em vias públicas | K5: 39020
B6: 1298 | C6: =VLOOKUP(B6,'subtipo ativo'!A:M,2,0) -> COMLURB - Companhia Municipal de Limpeza Urbana | D6: Remoção de resíduos em vias públicas | E6: 39020 | G6: =VLOOKUP(H6,B:E,1,0) -> 1287 | H6: 1287 | I6: =VLOOKUP(H6,'subtipo ativo'!A:M,2,0) -> COMLURB - Companhia Municipal de Limpeza Urbana | J6: Varrição de vias públicas | K6: 25093
B7: 100 | C7: =VLOOKUP(B7,'subtipo ativo'!A:M,2,0) -> CGC - Coordenadoria Geral de Conservação | D7: Manutenção/Desobstrução de ramais de águas pluviais e ralos | E7: 34547 | G7: =VLOOKUP(H7,B:E,1,0) -> 5806 | H7: 5806 | I7: =VLOOKUP(H7,'subtipo ativo'!A:M,2,0) -> Ouvidoria SMTR | J7: Fiscalização de má condição do ônibus | K7: 10315
B8: 5071 | C8: =VLOOKUP(B8,'subtipo ativo'!A:M,2,0) -> GM-RIO - Guarda Municipal do Rio de Janeiro | D8: Fiscalização de perturbação do sossego | E8: 31338 | G8: =VLOOKUP(H8,B:E,1,0) -> 1295 | H8: 1295 | I8: =VLOOKUP(H8,'subtipo ativo'!A:M,2,0) -> COMLURB - Companhia Municipal de Limpeza Urbana | J8: Remoção de resíduos de poda | K8: 6837
B9: 1316 | C9: =VLOOKUP(B9,'subtipo ativo'!A:M,2,0) -> COMLURB - Companhia Municipal de Limpeza Urbana | D9: Controle de roedores e caramujos africanos | E9: 26410 | G9: =VLOOKUP(H9,B:E,1,0) -> #N/A | H9: 6159 | I9: =VLOOKUP(H9,'subtipo ativo'!A:M,2,0) -> Ouvidoria SMTR | J9: Jaé - Bilhetagem eletrônica | K9: 6261
B10: 1319 | C10: =VLOOKUP(B10,'subtipo ativo'!A:M,2,0) -> COMLURB - Companhia Municipal de Limpeza Urbana | D10: Poda de árvore em vias públicas | E10: 26052 | G10: =VLOOKUP(H10,B:E,1,0) -> 1286 | H10: 1286 | I10: =VLOOKUP(H10,'subtipo ativo'!A:M,2,0) -> COMLURB - Companhia Municipal de Limpeza Urbana | J10: Limpeza de ralos | K10: 4418
B11: 1287 | C11: =VLOOKUP(B11,'subtipo ativo'!A:M,2,0) -> COMLURB - Companhia Municipal de Limpeza Urbana | D11: Varrição de vias públicas | E11: 25093 | G11: =VLOOKUP(H11,B:E,1,0) -> 2630 | H11: 2630 | I11: =VLOOKUP(H11,'subtipo ativo'!A:M,2,0) -> COMLURB - Companhia Municipal de Limpeza Urbana | J11: Limpeza de praças e parques | K11: 4200
B12: 5813 | C12: =VLOOKUP(B12,'subtipo ativo'!A:M,2,0) -> SMTR - Secretaria Municipal de Transportes | D12: Fiscalização de má conduta do motorista/despachante | E12: 22804 | G12: =VLOOKUP(H12,B:E,1,0) -> #N/A | H12: 3366 | I12: =VLOOKUP(H12,'subtipo ativo'!A:M,2,0) -> Ouvidoria CCU | J12: Comércio Ambulante | K12: 3295
B13: 1274 | C13: =VLOOKUP(B13,'subtipo ativo'!A:M,2,0) -> COMLURB - Companhia Municipal de Limpeza Urbana | D13: Verificação de frequência irregular da coleta domiciliar com retirada do resíduo | E13: 21894 | G13: =VLOOKUP(H13,B:E,1,0) -> 1292 | H13: 1292 | I13: =VLOOKUP(H13,'subtipo ativo'!A:M,2,0) -> COMLURB - Companhia Municipal de Limpeza Urbana | J13: Notificação ao proprietário para limpeza de resíduos em terreno baldio | K13: 2938
... B266: 2613 | C266: =VLOOKUP(B266,'subtipo ativo'!A:M,2,0) -> GC | D266: Vistoria em alteração no nível de água na Lagoa Rodrigo de Freitas | E266: 0 | G266: =VLOOKUP(H266,B:E,1,0) -> #N/A | H266: 6302 | I266: =VLOOKUP(H266,'subtipo ativo'!A:M,2,0) -> Ouvidoria RioSaúde | J266: Processos e Documentos Administrativos (DOCUMENTAL) - CER RioSaúde | K266: 1
G267: =VLOOKUP(H267,B:E,1,0) -> #N/A | H267: 6087 | I267: =VLOOKUP(H267,'subtipo ativo'!A:M,2,0) -> TR/SETT - Licenciamento | J267: Publicidade em táxi - SETT | K267: 1
G268: =VLOOKUP(H268,B:E,1,0) -> #N/A | H268: 6355 | I268: =VLOOKUP(H268,'subtipo ativo'!A:M,2,0) -> Ouvidoria RioSaúde | J268: Qualidade das informações recebidas - HM RioSaúde | K268: 1
G269: =VLOOKUP(H269,B:E,1,0) -> #N/A | H269: 6178 | I269: =VLOOKUP(H269,'subtipo ativo'!A:M,2,0) -> Ouvidoria SEAC | J269: Recicla Comunidade | K269: 1
G270: =VLOOKUP(H270,B:E,1,0) -> #N/A | H270: 6328 | I270: =VLOOKUP(H270,'subtipo ativo'!A:M,2,0) -> Ouvidoria RioSaúde | J270: Regulação Procedimentos - HM RioSaúde | K270: 1
G271: =VLOOKUP(H271,B:E,1,0) -> #N/A | H271: 6215 | I271: =VLOOKUP(H271,'subtipo ativo'!A:M,2,0) -> OUVIDORIA IVISA | J271: Servidor - LASP | K271: 1
G272: =VLOOKUP(H272,B:E,1,0) -> #N/A | H272: 5827 | I272: =VLOOKUP(H272,'subtipo ativo'!A:M,2,0) -> Ouvidoria SMDU | J272: Situação de nota de débito na SMDU | K272: 1
G273: =VLOOKUP(H273,B:E,1,0) -> #N/A | H273: 6180 | I273: =VLOOKUP(H273,'subtipo ativo'!A:M,2,0) -> Ouvidoria SEAC | J273: Turistando com a Comunidade | K273: 1
G274: =VLOOKUP(H274,B:E,1,0) -> #N/A | H274: 6334 | I274: =VLOOKUP(H274,'subtipo ativo'!A:M,2,0) -> Ouvidoria RioSaúde | J274: Adequação da classificação de risco - HM RioSaúde | K274: 0
G275: =VLOOKUP(H275,B:E,1,0) -> #N/A | H275: 6307 | I275: =VLOOKUP(H275,'subtipo ativo'!A:M,2,0) -> Ouvidoria RioSaúde | J275: Atendimento do Administrativo - CER RioSaúde | K275: 0
G276: =VLOOKUP(H276,B:E,1,0) -> #N/A | H276: 6339 | I276: =VLOOKUP(H276,'subtipo ativo'!A:M,2,0) -> Ouvidoria RioSaúde | J276: Atendimento do Administrativo - HM RioSaúde | K276: 0
G277: =VLOOKUP(H277,B:E,1,0) -> #N/A | H277: 6330 | I277: =VLOOKUP(H277,'subtipo ativo'!A:M,2,0) -> Ouvidoria RioSaúde | J277: Atendimento do Agente de Portaria - HM RioSaúde | K277: 0
G278: =VLOOKUP(H278,B:E,1,0) -> #N/A | H278: 6341 | I278: =VLOOKUP(H278,'subtipo ativo'!A:M,2,0) -> Ouvidoria RioSaúde | J278: Atendimento do Enfermeiro - HM RioSaúde | K278: 0
... G321: =VLOOKUP(H321,B:E,1,0) -> #N/A | H321: 5143 | I321: =VLOOKUP(H321,'subtipo ativo'!A:M,2,0) -> Ouvidoria SEOP | J321: Vans e Kombis | K321: 0

Sheet SERVIÇOS FINAL
A1: volume de chamados fev25 a fev26 | B1: ID_Subtipo | C1: UO | D1: Subtipos de Serviços | E1: Volume | F1: Representatividade | G1: Acumulado | H1: Qtd acesso/dia por 1 ano | I1: Revisão? | N1: Solicitável? | O1: Manter? | P1: Ouvidoria?
A2: =SUM(E2:E267) -> 998396 | B2: 2966 | C2: =VLOOKUP(B2,'subtipo ativo'!A:M,2,0) -> GM-RIO - Guarda Municipal do Rio de Janeiro | D2: Fiscalização de estacionamento irregular de veículo | E2: 201219 | F2: =E2/A$2 -> 0.20154227 | G2: =F2 -> 0.20154227 | H2: =E2/365 -> 551.28493 | N2: S | O2: S | P2: N/A
B3: 1325 | C3: =VLOOKUP(B3,'subtipo ativo'!A:M,2,0) -> COMLURB - Companhia Municipal de Limpeza Urbana | D3: Remoção de entulho | E3: 135183 | F3: =E3/A$2 -> 0.13540018 | G3: =G2+F3 -> 0.33694246 | H3: =E3/365 -> 370.36438 | N3: S | O3: N | P3: N/A
B4: 5799 | C4: =VLOOKUP(B4,'subtipo ativo'!A:M,2,0) -> Ouvidoria RIOLUZ | D4: Reparo de luminária | E4: 91196 | F4: =E4/A$2 -> 0.091342513 | G4: =G3+F4 -> 0.42828497 | H4: =E4/365 -> 249.85205 | N4: N | O4: N | P4: N/A
B5: 78 | C5: =VLOOKUP(B5,'subtipo ativo'!A:M,2,0) -> CGC - Coordenadoria Geral de Conservação | D5: Reparo de buraco, deformação ou afundamento na pista | E5: 51060 | F5: =E5/A$2 -> 0.051142032 | G5: =G4+F5 -> 0.479427 | H5: =E5/365 -> 139.89041 | N5: S | O5: S | P5: N/A
B6: 1298 | C6: =VLOOKUP(B6,'subtipo ativo'!A:M,2,0) -> COMLURB - Companhia Municipal de Limpeza Urbana | D6: Remoção de resíduos em vias públicas | E6: 39020 | F6: =E6/A$2 -> 0.039082689 | G6: =G5+F6 -> 0.51850969 | H6: =E6/365 -> 106.90411 | N6: S | O6: S | P6: N/A
B7: 100 | C7: =VLOOKUP(B7,'subtipo ativo'!A:M,2,0) -> CGC - Coordenadoria Geral de Conservação | D7: Manutenção/Desobstrução de ramais de águas pluviais e ralos | E7: 34547 | F7: =E7/A$2 -> 0.034602502 | G7: =G6+F7 -> 0.55311219 | H7: =E7/365 -> 94.649315
B8: 5071 | C8: =VLOOKUP(B8,'subtipo ativo'!A:M,2,0) -> GM-RIO - Guarda Municipal do Rio de Janeiro | D8: Fiscalização de perturbação do sossego | E8: 31338 | F8: =E8/A$2 -> 0.031388347 | G8: =G7+F8 -> 0.58450054 | H8: =E8/365 -> 85.857534
B9: 1316 | C9: =VLOOKUP(B9,'subtipo ativo'!A:M,2,0) -> COMLURB - Companhia Municipal de Limpeza Urbana | D9: Controle de roedores e caramujos africanos | E9: 26410 | F9: =E9/A$2 -> 0.02645243 | G9: =G8+F9 -> 0.61095297 | H9: =E9/365 -> 72.356164
B10: 1319 | C10: =VLOOKUP(B10,'subtipo ativo'!A:M,2,0) -> COMLURB - Companhia Municipal de Limpeza Urbana | D10: Poda de árvore em vias públicas | E10: 26052 | F10: =E10/A$2 -> 0.026093855 | G10: =G9+F10 -> 0.63704682 | H10: =E10/365 -> 71.375342
B11: 1287 | C11: =VLOOKUP(B11,'subtipo ativo'!A:M,2,0) -> COMLURB - Companhia Municipal de Limpeza Urbana | D11: Varrição de vias públicas | E11: 25093 | F11: =E11/A$2 -> 0.025133314 | G11: =G10+F11 -> 0.66218014 | H11: =E11/365 -> 68.747945
B12: 5813 | C12: =VLOOKUP(B12,'subtipo ativo'!A:M,2,0) -> SMTR - Secretaria Municipal de Transportes | D12: Fiscalização de má conduta do motorista/despachante | E12: 22804 | F12: =E12/A$2 -> 0.022840636 | G12: =G11+F12 -> 0.68502077 | H12: =E12/365 -> 62.476712 | N12: S | O12: S | P12: N/A
B13: 1274 | C13: =VLOOKUP(B13,'subtipo ativo'!A:M,2,0) -> COMLURB - Companhia Municipal de Limpeza Urbana | D13: Verificação de frequência irregular da coleta domiciliar com retirada do resíduo | E13: 21894 | F13: =E13/A$2 -> 0.021929174 | G13: =G12+F13 -> 0.70694995 | H13: =E13/365 -> 59.983562 | N13: S | O13: N | P13: S
B14: 1242 | C14: =VLOOKUP(B14,'subtipo ativo'!A:M,2,0) -> SMTR - Secretaria Municipal de Transportes | D14: Verificação de ar condicionado inoperante no ônibus | E14: 20442 | F14: =E14/A$2 -> 0.020474842 | G14: =G13+F14 -> 0.72742479 | H14: =E14/365 -> 56.005479 | N14: S | O14: S
B15: 1279 | C15: =VLOOKUP(B15,'subtipo ativo'!A:M,2,0) -> COMLURB - Companhia Municipal de Limpeza Urbana | D15: Capina em vias públicas | E15: 18735 | F15: =E15/A$2 -> 0.018765099 | G15: =G14+F15 -> 0.74618989 | H15: =E15/365 -> 51.328767 | N15: N/A | O15: N/A | P15: N/A
B16: 2178 | C16: =VLOOKUP(B16,'subtipo ativo'!A:M,2,0) -> CGC - Coordenadoria Geral de Conservação | D16: Reposição de Grelha ou Tampão | E16: 15598 | F16: =E16/A$2 -> 0.015623059 | G16: =G15+F16 -> 0.76181295 | H16: =E16/365 -> 42.734247
B17: 3139 | C17: =VLOOKUP(B17,'subtipo ativo'!A:M,2,0) -> GMA - Gerência de Manutenção Semafórica | D17: Reparo de sinal de trânsito apagado | E17: 15068 | F17: =E17/A$2 -> 0.015092208 | G17: =G16+F17 -> 0.77690516 | H17: =E17/365 -> 41.282192
B18: 1131 | C18: =VLOOKUP(B18,'subtipo ativo'!A:M,2,0) -> SMAC - Secretaria Municipal de Meio Ambiente da Cidade | D18: Resgate de animais silvestres | E18: 11741 | F18: =E18/A$2 -> 0.011759863 | G18: =G17+F18 -> 0.78866502 | H18: =E18/365 -> 32.167123
B19: 5806 | C19: =VLOOKUP(B19,'subtipo ativo'!A:M,2,0) -> Ouvidoria SMTR | D19: Fiscalização de má condição do ônibus | E19: 10315 | F19: =E19/A$2 -> 0.010331572 | G19: =G18+F19 -> 0.79899659 | H19: =E19/365 -> 28.260274
B20: 2806 | C20: =VLOOKUP(B20,'subtipo ativo'!A:M,2,0) -> GFER - Gerência de Fiscalização de Estacionamentos e Reboques | D20: Remoção de veículo abandonado em via pública | E20: 9177 | F20: =E20/A$2 -> 0.0091917436 | G20: =G19+F20 -> 0.80818833 | H20: =E20/365 -> 25.142466
B21: 2345 | C21: =VLOOKUP(B21,'subtipo ativo'!A:M,2,0) -> SMDU - Secretaria Municipal de Desenvolvimento Urbano e Licenciamento | D21: Fiscalização de obras em imóvel privado | E21: 8061 | F21: =E21/A$2 -> 0.0080739506 | G21: =G20+F21 -> 0.81626228 | H21: =E21/365 -> 22.084932
B22: 1295 | C22: =VLOOKUP(B22,'subtipo ativo'!A:M,2,0) -> COMLURB - Companhia Municipal de Limpeza Urbana | D22: Remoção de resíduos de poda | E22: 6837 | F22: =E22/A$2 -> 0.0068479842 | G22: =G21+F22 -> 0.82311027 | H22: =E22/365 -> 18.731507
B23: 2100 | C23: =VLOOKUP(B23,'subtipo ativo'!A:M,2,0) -> SMPDA - Secretaria Municipal de Proteção e Defesa dos Animais | D23: Vistoria técnica em situações de maus tratos de animais domésticos | E23: 6616 | F23: =E23/A$2 -> 0.0066266291 | G23: =G22+F23 -> 0.8297369 | H23: =E23/365 -> 18.126027
B24: 5807 | C24: =VLOOKUP(B24,'subtipo ativo'!A:M,2,0) -> CVA - Coordenação de Vigilância de Alimentos | D24: Fiscalização sanitária em serviços de alimentos e ensino | E24: 5924 | F24: =E24/A$2 -> 0.0059335174 | G24: =G23+F24 -> 0.83567042 | H24: =E24/365 -> 16.230137
B25: 82 | C25: =VLOOKUP(B25,'subtipo ativo'!A:M,2,0) -> CGC - Coordenadoria Geral de Conservação | D25: Fiscalização de buraco na calçada | E25: 5639 | F25: =E25/A$2 -> 0.0056480595 | G25: =G24+F25 -> 0.84131847 | H25: =E25/365 -> 15.449315
B26: 2819 | C26: =VLOOKUP(B26,'subtipo ativo'!A:M,2,0) -> Central de Ambulâncias | D26: Solicitação de transporte da gestante para a maternidade | E26: 5376 | F26: =E26/A$2 -> 0.005384637 | G26: =G25+F26 -> 0.84670311 | H26: =E26/365 -> 14.728767
B27: 999 | C27: =VLOOKUP(B27,'subtipo ativo'!A:M,2,0) -> CVAS - Coordenação de Vigilância Ambiental em Saúde | D27: Vistoria em foco de Aedes Aegypti (Dengue, Chikungunya e Zika) | E27: 5300 | F27: =E27/A$2 -> 0.0053085149 | G27: =G26+F27 -> 0.85201163 | H27: =E27/365 -> 14.520548
... B71: 216 | C71: =VLOOKUP(B71,'subtipo ativo'!A:M,2,0) -> CET-RIO - Companhia de Engenharia de Tráfego do RJ | D71: Manutenção de sinalização gráfica horizontal viária | E71: 1074 | F71: =E71/A$2 -> 0.0010757255 | G71: =G70+F71 -> 0.96378792 | H71: =E71/365 -> 2.9424658
B72: 5689 | C72: =VLOOKUP(B72,'subtipo ativo'!A:M,2,0) -> Conselhos Tutelares | D72: Solicitação de atendimento do Conselho Tutelar | E72: 990 | F72: =E72/A$2 -> 0.00099159051 | G72: =G71+F72 -> 0.96477951 | H72: =E72/365 -> 2.7123288 | P72: S
B73: 5854 | C73: =VLOOKUP(B73,'subtipo ativo'!A:M,2,0) -> CES - Coordenação de Engenharia Sanitária | D73: Fiscalização sanitária de estabelecimentos comerciais em geral | E73: 930 | F73: =E73/A$2 -> 0.00093149412 | G73: =G72+F73 -> 0.965711 | H73: =E73/365 -> 2.5479452
B74: 5867 | C74: =VLOOKUP(B74,'subtipo ativo'!A:M,2,0) -> CMTC - Companhia Municipal de Transportes Coletivos | D74: Verificação de ocorrências no BRT - Transoeste | E74: 886 | F74: =E74/A$2 -> 0.00088742343 | G74: =G73+F74 -> 0.96659842 | H74: =E74/365 -> 2.4273973
B75: 1289 | C75: =VLOOKUP(B75,'subtipo ativo'!A:M,2,0) -> COMLURB - Companhia Municipal de Limpeza Urbana | D75: Limpeza de margens de rios | E75: 876 | F75: =E75/A$2 -> 0.00087740736 | G75: =G74+F75 -> 0.96747583 | H75: =E75/365 -> 2.4
B76: 1746 | C76: =VLOOKUP(B76,'subtipo ativo'!A:M,2,0) -> GTP-6 | D76: Captura para análise de morcegos caídos ou que atacaram pessoas e/ou animais | E76: 837 | F76: =E76/A$2 -> 0.0008383447 | G76: =G75+F76 -> 0.96831418 | H76: =E76/365 -> 2.2931507
B77: 1363 | C77: =VLOOKUP(B77,'subtipo ativo'!A:M,2,0) -> COMLURB - Companhia Municipal de Limpeza Urbana | D77: Manutenção de mobiliário, brinquedos e equipamentos esportivos em praças e parques públicos | E77: 829 | F77: =E77/A$2 -> 0.00083033185 | G77: =G76+F77 -> 0.96914451 | H77: =E77/365 -> 2.2712329
B78: 5856 | C78: =VLOOKUP(B78,'subtipo ativo'!A:M,2,0) -> SMTR - Secretaria Municipal de Transportes | D78: Solicitação de implantação ou remanejamento de ponto de ônibus | E78: 813 | F78: =E78/A$2 -> 0.00081430615 | G78: =G77+F78 -> 0.96995881 | H78: =E78/365 -> 2.2273973
B79: 2960 | C79: =VLOOKUP(B79,'subtipo ativo'!A:M,2,0) -> GTP-3 | D79: Avaliação de cães e gatos com suspeita de raiva | E79: 802 | F79: =E79/A$2 -> 0.00080328847 | G79: =G78+F79 -> 0.9707621 | H79: =E79/365 -> 2.1972603
B80: 3164 | C80: =VLOOKUP(B80,'subtipo ativo'!A:M,2,0) -> GTP-2 | D80: Vistoria em logradouros públicos ou privados para avaliação de gatos errantes com suspeita de Esporotricose | E80: 760 | F80: =E80/A$2 -> 0.000761221 | G80: =G79+F80 -> 0.97152332 | H80: =E80/365 -> 2.0821918
B81: 5847 | C81: =VLOOKUP(B81,'subtipo ativo'!A:M,2,0) -> CVS - Coordenação de Vigilância em Serviços e Produtos de Interesse à Saúde | D81: Fiscalização sanitária em serviços de embelezamento e atividades físicas | E81: 756 | F81: =E81/A$2 -> 0.00075721457 | G81: =G80+F81 -> 0.97228054 | H81: =E81/365 -> 2.0712329
B82: 144 | C82: =VLOOKUP(B82,'subtipo ativo'!A:M,2,0) -> Patrimônio | D82: Instalação, remoção e manutenção de placa com nome de rua | E82: 710 | F82: =E82/A$2 -> 0.00071114067 | G82: =G81+F82 -> 0.97299168 | H82: =E82/365 -> 1.9452055
B83: 1909 | C83: =VLOOKUP(B83,'subtipo ativo'!A:M,2,0) -> Assistencia Social | D83: Solicitação de Atendimento social | E83: 699 | F83: =E83/A$2 -> 0.000700123 | G83: =G82+F83 -> 0.9736918 | H83: =E83/365 -> 1.9150685
...

Sheet REVISAO FORMS SERVIÇOS
A1: ORGÃO | B1: SERVIÇO | C1: Qtd chamados fev25 a fev26 | D1: Representatividade | E1: Acumulado | F1: Elegível a revisão inicial? | G1: Responsável pela revisão | H1: Grupo revisor
A2: GM-RIO - Guarda Municipal do Rio de Janeiro | B2: Fiscalização de estacionamento irregular de veículo | C2: 201219 | D2: 0.20154227 | E2: 0.20154227 | F2: Sim | G2: Patrick | H2: Patrick+Felipe
A3: COMLURB - Companhia Municipal de Limpeza Urbana | B3: Remoção de entulho | C3: 135183 | D3: 0.13540018 | E3: 0.33694246 | F3: Sim | G3: Felipe | H3: Felipe+Costa | L3: < Felipe único que faz SIM e NÂO
A4: Ouvidoria RIOLUZ | B4: Reparo de luminária | C4: 91196 | D4: 0.091342513 | E4: 0.42828497 | F4: Sim | G4: Costa | H4: Costa+Pedro
A5: CGC - Coordenadoria Geral de Conservação | B5: Reparo de buraco, deformação ou afundamento na pista | C5: 51060 | D5: 0.051142032 | E5: 0.479427 | F5: Não (endereço e descrição) | G5: Pedro | H5: Costa+Pedro
A6: COMLURB - Companhia Municipal de Limpeza Urbana | B6: Remoção de resíduos em vias públicas | C6: 39020 | D6: 0.039082689 | E6: 0.51850969 | F6: Não (endereço e descrição) | G6: Felipe | H6: Felipe+Costa
A7: CGC - Coordenadoria Geral de Conservação | B7: Manutenção/Desobstrução de ramais de águas pluviais e ralos | C7: 34547 | D7: 0.034602502 | E7: 0.55311219 | F7: Não (endereço e descrição) | G7: Pedro | H7: Costa+Pedro
A8: GM-RIO - Guarda Municipal do Rio de Janeiro | B8: Fiscalização de perturbação do sossego | C8: 31338 | D8: 0.031388347 | E8: 0.58450054 | F8: Sim | G8: Patrick | H8: Patrick+Felipe
A9: COMLURB - Companhia Municipal de Limpeza Urbana | B9: Controle de roedores e caramujos africanos | C9: 26410 | D9: 0.02645243 | E9: 0.61095297 | F9: Não (endereço e descrição) | G9: Felipe | H9: Felipe+Costa
A10: COMLURB - Companhia Municipal de Limpeza Urbana | B10: Poda de árvore em vias públicas | C10: 26052 | D10: 0.026093855 | E10: 0.63704682 | F10: Não (endereço e descrição) | G10: Felipe | H10: Felipe+Costa
A11: COMLURB - Companhia Municipal de Limpeza Urbana | B11: Varrição de vias públicas | C11: 25093 | D11: 0.025133314 | E11: 0.66218014 | F11: Não (endereço e descrição) | G11: Felipe | H11: Felipe+Costa
A12: SMTR - Secretaria Municipal de Transportes | B12: Fiscalização de má conduta do motorista/despachante | C12: 22804 | D12: 0.022840636 | E12: 0.68502077 | F12: Sim | G12: Costa | H12: Costa+Pedro
A13: COMLURB - Companhia Municipal de Limpeza Urbana | B13: Verificação de frequência irregular da coleta domiciliar com retirada do resíduo | C13: 21894 | D13: 0.021929174 | E13: 0.70694995 | F13: Não (endereço e descrição) | G13: Felipe | H13: Felipe+Costa
A14: SMTR - Secretaria Municipal de Transportes | B14: Verificação de ar condicionado inoperante no ônibus | C14: 20442 | D14: 0.020474842 | E14: 0.72742479 | F14: Sim | G14: Costa | H14: Costa+Pedro
A15: COMLURB - Companhia Municipal de Limpeza Urbana | B15: Capina em vias públicas | C15: 18735 | D15: 0.018765099 | E15: 0.74618989 | F15: Não (endereço e descrição) | G15: Felipe | H15: Felipe+Costa
... A38: CLF - Coordenadoria de Licenciamento e Fiscalização | B38: Fiscalização de atividades econômicas sem alvará | C38: 3358 | D38: 0.0033633949 | E38: 0.90114744 | F38: Sim | G38: Patrick | H38: Patrick+Felipe

Sheet Controle CRC
A1: Subtipo | B1: Atributo | C1: Quais?
A2: Remoção de entulho
A3: Remoção de resíduos em vias públicas | B3: Não tem atributo especifico
A4: Controle de roedores e caramujos africanos | B4: Não tem atributo especifico
A5: Poda de árvore em vias públicas | B5: Não tem atributo especifico
A6: Varrição de vias públicas | B6: Não tem atributo especifico
A7: Verificação de frequência irregular da coleta domiciliar com retirada do resíduo | B7: Não tem atributo especifico
A8: Capina em vias públicas | B8: Não tem atributo especifico
A9: Remoção de resíduos de poda | B9: Não tem atributo especifico
A10: Remoção de árvore em logradouro | B10: Não tem atributo especifico
A11: Avaliação de risco de queda da árvore | B11: Não tem atributo especifico
A12: Limpeza de ralos | B12: Não tem atributo especifico
A13: Limpeza de praças e parques | B13: Não tem atributo especifico

Sheet INFO FINAL
B1: TEM SERVIÇO? | C1: ID_Subtipo | D1: UO | E1: Subtipos de Informações | F1: Volume | G1: Representatividade | H1: Qtd acesso/dia por 1 ano | M1: Solicitável? | N1: Manter?
A2: =SUM(F2:F300) -> 33360 | B2: #N/A | C2: 6159 | D2: Ouvidoria SMTR | E2: Jaé - Bilhetagem eletrônica | F2: 6261 | G2: =F2/A$2 -> 0.18767986 | H2: =F2/365 -> 17.153425 | N2: S
B3: #N/A | C3: 3366 | D3: Ouvidoria CCU | E3: Comércio Ambulante | F3: 3295 | G3: =F3/A$2 -> 0.098770983 | H3: =F3/365 -> 9.0273973 | M3: S
B4: #N/A | C4: 3523 | D4: LAI-Coordenadoria Técnica de Transparência | E4: Pedido de Acesso à Informação (LAI) | F4: 2649 | G4: =F4/A$2 -> 0.079406475 | H4: =F4/365 -> 7.2575342
B5: #N/A | C5: 3167 | D5: PREVI-RIO - Instituto de Previdência e Assistência | E5: Informações sobre o Recadastramento Anual / Prova de Vida | F5: 1743 | G5: =F5/A$2 -> 0.052248201 | H5: =F5/365 -> 4.7753425
B6: #N/A | C6: 5874 | D6: Ouvidoria GBP | E6: Fiscalização de fechamento de logradouro público | F6: 1457 | G6: =F6/A$2 -> 0.04367506 | H6: =F6/365 -> 3.9917808
B7: #N/A | C7: 2702 | D7: PREVI-RIO - Instituto de Previdência e Assistência | E7: Informações sobre Pecúlio | F7: 981 | G7: =F7/A$2 -> 0.029406475 | H7: =F7/365 -> 2.6876712
B8: #N/A | C8: 2708 | D8: GAT - Gerência de Atendimento | E8: Contracheque de servidor inativo e pensionista | F8: 977 | G8: =F8/A$2 -> 0.029286571 | H8: =F8/365 -> 2.6767123
B9: #N/A | C9: 5849 | D9: Ouvidoria SMAS | E9: Informações sobre ações de acolhimento a pessoas em situação de rua | F9: 789 | G9: =F9/A$2 -> 0.023651079 | H9: =F9/365 -> 2.1616438
B10: #N/A | C10: 2704 | D10: PREVI-RIO - Instituto de Previdência e Assistência | E10: Informações sobre pensão post-mortem | F10: 767 | G10: =F10/A$2 -> 0.022991607 | H10: =F10/365 -> 2.1013699
B11: #N/A | C11: 6004 | D11: Ouvidoria SMS | E11: Clínicas da Família | F11: 643 | G11: =F11/A$2 -> 0.01927458 | H11: =F11/365 -> 1.7616438
B12: #N/A | C12: 2408 | D12: PREVI-RIO - Instituto de Previdência e Assistência | E12: Isenção de Imposto de Renda | F12: 576 | G12: =F12/A$2 -> 0.017266187 | H12: =F12/365 -> 1.5780822
B13: #N/A | C13: 5804 | D13: Ouvidoria SMTR | E13: Fiscalização de irregularidades em linha de ônibus | F13: 573 | G13: =F13/A$2 -> 0.017176259 | H13: =F13/365 -> 1.569863
B14: #N/A | C14: 2695 | D14: PREVI-RIO - Instituto de Previdência e Assistência | E14: Informações sobre o auxílio educação | F14: 550 | G14: =F14/A$2 -> 0.016486811 | H14: =F14/365 -> 1.5068493
B15: #N/A | C15: 2697 | D15: PREVI-RIO - Instituto de Previdência e Assistência | E15: Informações sobre o auxílio funeral | F15: 424 | G15: =F15/A$2 -> 0.012709832 | H15: =F15/365 -> 1.1616438
... B300: #N/A | C300: 5143 | D300: Ouvidoria SEOP | E300: Vans e Kombis | F300: 0 | G300: =F300/A$2 -> 0 | H300: =F300/365 -> 0

Sheet base chamados
A1: id_subtipo | B1: no_subtipo | C1: no_categoria | D1: Mês | E1: Ano | F1: vol
A2: 1900 | B2: Informações sobre inscrição e atualização do Cadastro Único | C2: Informações | D2: 7 | E2: 2025 | F2: 18832
A3: 2966 | B3: Fiscalização de estacionamento irregular de veículo | C3: Serviço | D3: 7 | E3: 2025 | F3: 17606
A4: 2966 | B4: Fiscalização de estacionamento irregular de veículo | C4: Serviço | D4: 5 | E4: 2025 | F4: 16781
A5: 2966 | B5: Fiscalização de estacionamento irregular de veículo | C5: Serviço | D5: 8 | E5: 2025 | F5: 16730
A6: 2966 | B6: Fiscalização de estacionamento irregular de veículo | C6: Serviço | D6: 9 | E6: 2025 | F6: 16356
A7: 2966 | B7: Fiscalização de estacionamento irregular de veículo | C7: Serviço | D7: 10 | E7: 2025 | F7: 15745
A8: 2966 | B8: Fiscalização de estacionamento irregular de veículo | C8: Serviço | D8: 6 | E8: 2025 | F8: 15684
A9: 2966 | B9: Fiscalização de estacionamento irregular de veículo | C9: Serviço | D9: 11 | E9: 2025 | F9: 15269
A10: 2966 | B10: Fiscalização de estacionamento irregular de veículo | C10: Serviço | D10: 12 | E10: 2025 | F10: 15266
A11: 1900 | B11: Informações sobre inscrição e atualização do Cadastro Único | C11: Informações | D11: 9 | E11: 2025 | F11: 15251
A12: 2966 | B12: Fiscalização de estacionamento irregular de veículo | C12: Serviço | D12: 1 | E12: 2026 | F12: 14896
A13: 2966 | B13: Fiscalização de estacionamento irregular de veículo | C13: Serviço | D13: 3 | E13: 2025 | F13: 14803
... A14335: 1623 | B14335: Informações sobre processos e recursos ao Conselho de Contribuintes | C14335: Informações | D14335: 1 | E14335: 2026 | F14335: 1

Sheet subtipo ativo
A1: id_subtipo | B1: no_unidade_organizacional | C1: no_categoria | D1: id_classificacao | E1: id_tipo | F1: no_tipo | G1: no_subtipo | H1: Subtipo Ativo | I1: Classificação Ativa | J1: fl_nao_selecionavel_atendimento | K1: fl_resolver | L1: fl_encaminhar | M1: fl_Ouvidoria
A2: 5192 | B2: GFER - Gerência de Fiscalização de Estacionamentos e Reboques | C2: Serviço | D2: 11519 | E2: 19 | F2: Estacionamento | G2: Fiscalização da atuação do guardador de estacionamento Rio Rotativo | H2: 1 | I2: 1 | J2: 0 | K2: 0 | L2: 1 | M2: 0
A3: 5870 | B3: Ouvidoria SUPPA | C3: Informações | D3: 18392 | E3: 10 | F3: Mobiliário Urbano | G3: Abrigo de ônibus - Instalação | H3: 1 | I3: 1 | J3: 0 | K3: 0 | L3: 1 | M3: 1
A4: 4452 | B4: Ouvidoria SMS | C4: Informações | D4: 9055 | E4: 1614 | F4: Medicamentos | G4: Acesso à medicamentos | H4: 1 | I4: 1 | J4: 0 | K4: 0 | L4: 1 | M4: 1
A5: 6158 | B5: Ouvidoria COMLURB | C5: Informações | D5: 19666 | E5: 1043 | F5: Limpeza de logradouros | G5: Acidentes com veículos ou equipamentos da COMLURB | H5: 1 | I5: 1 | J5: 0 | K5: 0 | L5: 1 | M5: 1
A6: 2112 | B6: SMPD - Secretaria Municipal da Pessoa com Deficiência | C6: Informações | D6: 2462 | E6: 514 | F6: Atendimento para pessoas com deficiência | G6: Acolhimento em Residência Inclusiva para pessoas com deficiência | H6: 1 | I6: 1 | J6: 0 | K6: 1 | L6: 0 | M6: 0
A7: 6196 | B7: PROCON CARIOCA - Instituto Municipal de Defesa do Consumidor | C7: Serviço | D7: 19798 | E7: 1452 | F7: Defesa do Consumidor | G7: Acompanhamento de solicitação no Procon Carioca | H7: 1 | I7: 1 | J7: 0 | K7: 0 | L7: 1 | M7: 0
A8: 6303 | B8: Ouvidoria RioSaúde | C8: Informações | D8: 20105 | E8: 1704 | F8: Coordenação de Emergência Regional - RioSaúde | G8: Adequação da classificação de risco - CER RioSaúde | H8: 1 | I8: 1 | J8: 0 | K8: 1 | L8: 0 | M8: 1
A9: 6334 | B9: Ouvidoria RioSaúde | C9: Informações | D9: 20268 | E9: 1705 | F9: Hospitais - RioSaúde | G9: Adequação da classificação de risco - HM RioSaúde | H9: 1 | I9: 1 | J9: 0 | K9: 1 | L9: 0 | M9: 1
A10: 6368 | B10: Ouvidoria RioSaúde | C10: Informações | D10: 20366 | E10: 1706 | F10: Unidades de Pronto Atendimento (UPAs) - RioSaúde | G10: Adequação da classificação de risco - UPAs RioSaúde | H10: 1 | I10: 1 | J10: 0 | K10: 1 | L10: 0 | M10: 1
A11: 6304 | B11: Ouvidoria RioSaúde | C11: Informações | D11: 20109 | E11: 1704 | F11: Coordenação de Emergência Regional - RioSaúde | G11: Adequação da equipe - CER RioSaúde | H11: 1 | I11: 1 | J11: 0 | K11: 1 | L11: 0 | M11: 1
A12: 6335 | B12: Ouvidoria RioSaúde | C12: Informações | D12: 20272 | E12: 1705 | F12: Hospitais - RioSaúde | G12: Adequação da equipe - HM RioSaúde | H12: 1 | I12: 1 | J12: 0 | K12: 1 | L12: 0 | M12: 1
A13: 6369 | B13: Ouvidoria RioSaúde | C13: Informações | D13: 20370 | E13: 1706 | F13: Unidades de Pronto Atendimento (UPAs) - RioSaúde | G13: Adequação da equipe - UPAs RioSaúde | H13: 1 | I13: 1 | J13: 0 | K13: 1 | L13: 0 | M13: 1
... A586: 2100 | B586: SMPDA - Secretaria Municipal de Proteção e Defesa dos Animais | C586: Serviço | D586: 2434 | E586: 502 | F586: Proteção de animais | G586: Vistoria técnica em situações de maus tratos de animais domésticos | H586: 1 | I586: 1 | J586: 0 | K586: 0 | L586: 1 | M586: 0
